local _ = {name = "air", prob = 0}
local A = {
	name = "default:coral_skeleton",
	param2 = 1,
	prob = 255,
	force_place = true
}
local B = {
	name = "moreblocks:stair_coral_skeleton",
	param2 = 23,
	prob = 255,
	force_place = true
}
local C = {
	name = "moreblocks:stair_coral_skeleton",
	param2 = 21,
	prob = 255,
	force_place = true
}
local D = {
	name = "moreblocks:panel_coral_skeleton",
	param2 = 3,
	prob = 255,
	force_place = true
}
local E = {
	name = "moreblocks:panel_coral_skeleton",
	param2 = 1,
	prob = 255,
	force_place = true
}
local F = {
	name = "moreblocks:stair_coral_skeleton",
	param2 = 1,
	prob = 255,
	force_place = true
}
local G = {
	name = "moreblocks:panel_coral_skeleton",
	param2 = 21,
	prob = 255,
	force_place = true
}
local H = {
	name = "moreblocks:panel_coral_skeleton",
	param2 = 23,
	prob = 255,
	force_place = true
}
local I = {
	name = "moreblocks:stair_coral_skeleton",
	param2 = 3,
	prob = 255,
	force_place = true
}
local J = {
	name = "moreblocks:slope_coral_skeleton_half",
	param2 = 19,
	prob = 255,
	force_place = true
}
local K = {
	name = "moreblocks:slope_coral_skeleton_half",
	param2 = 13,
	prob = 255,
	force_place = true
}
local L = {
	name = "moreblocks:stair_coral_skeleton",
	param2 = 0,
	prob = 255,
	force_place = true
}
local M = {
	name = "moreblocks:panel_coral_skeleton",
	param2 = 15,
	prob = 255,
	force_place = true
}
local N = {
	name = "moreblocks:slope_coral_skeleton_half",
	param2 = 1,
	prob = 255,
	force_place = true
}
local O = {
	name = "moreblocks:slab_coral_skeleton",
	param2 = 15,
	prob = 255,
	force_place = true
}
local P = {
	name = "moreblocks:slab_coral_skeleton",
	param2 = 17,
	prob = 255,
	force_place = true
}
local Q = {
	name = "moreblocks:slope_coral_skeleton_half",
	param2 = 3,
	prob = 255,
	force_place = true
}
return {
	size = {x = 12, y = 7, z = 19},
	data = { -- note that data is upside down
		A, _, _, _, _, _, _, _, _, _, _, A,
		A, _, _, _, _, _, _, _, _, _, _, A,
		_, A, _, _, B, A, A, C, _, _, A, _,
		_, _, A, A, A, D, E, A, A, A, _, _,
		_, _, _, _, F, G, H, I, _, _, _, _,
		_, _, _, _, _, F, I, _, _, _, _, _,
		_, _, _, _, _, J, K, _, _, _, _, _,

		_, _, _, _, _, _, _, _, _, _, _, _,
		_, _, _, _, _, _, _, _, _, _, _, _,
		_, _, _, _, _, _, _, _, _, _, _, _,
		_, _, _, _, _, _, _, _, _, _, _, _,
		_, _, _, _, _, _, _, _, _, _, _, _,
		_, _, _, _, _, _, _, _, _, _, _, _,
		_, _, _, _, _, _, _, _, _, _, _, _,

		_, _, _, _, _, _, _, _, _, _, _, _,
		_, A, _, _, _, _, _, _, _, _, A, _,
		_, A, _, _, B, A, A, C, _, _, A, _,
		_, _, A, A, A, D, E, A, A, A, _, _,
		_, _, _, _, F, G, H, I, _, _, _, _,
		_, _, _, _, _, F, I, _, _, _, _, _,
		_, _, _, _, _, J, K, _, _, _, _, _,

		_, _, _, _, _, _, _, _, _, _, _, _,
		_, _, _, _, _, _, _, _, _, _, _, _,
		_, _, _, _, _, _, _, _, _, _, _, _,
		_, _, _, _, _, _, _, _, _, _, _, _,
		_, _, _, _, _, _, _, _, _, _, _, _,
		_, _, _, _, _, _, _, _, _, _, _, _,
		_, _, _, _, _, _, _, _, _, _, _, _,

		_, _, _, _, _, _, _, _, _, _, _, _,
		_, _, _, _, _, _, _, _, _, _, _, _,
		_, A, _, _, B, A, A, C, _, _, A, _,
		_, _, A, A, A, D, E, A, A, A, _, _,
		_, _, _, _, F, G, H, I, _, _, _, _,
		_, _, _, _, _, F, I, _, _, _, _, _,
		_, _, _, _, _, _, _, _, _, _, _, _,

		_, _, _, _, _, _, _, _, _, _, _, _,
		_, _, _, _, _, _, _, _, _, _, _, _,
		_, _, _, _, _, _, _, _, _, _, _, _,
		_, _, _, _, _, _, _, _, _, _, _, _,
		_, _, _, _, _, _, _, _, _, _, _, _,
		_, _, _, _, _, _, _, _, _, _, _, _,
		_, _, _, _, _, _, _, _, _, _, _, _,

		_, _, _, _, _, _, _, _, _, _, _, _,
		_, _, _, _, _, _, _, _, _, _, _, _,
		_, A, _, _, B, A, A, C, _, _, A, _,
		_, _, A, A, A, D, E, A, A, A, _, _,
		_, _, _, _, F, G, H, I, _, _, _, _,
		_, _, _, _, _, F, I, _, _, _, _, _,
		_, _, _, _, _, _, _, _, _, _, _, _,

		_, _, _, _, _, _, _, _, _, _, _, _,
		_, _, _, _, _, _, _, _, _, _, _, _,
		_, _, _, _, _, _, _, _, _, _, _, _,
		_, _, _, _, _, _, _, _, _, _, _, _,
		_, _, _, _, _, _, _, _, _, _, _, _,
		_, _, _, _, _, _, _, _, _, _, _, _,
		_, _, _, _, _, _, _, _, _, _, _, _,

		_, _, _, _, _, _, _, _, _, _, _, _,
		_, _, _, _, _, _, _, _, _, _, _, _,
		_, _, _, _, B, A, A, C, _, _, _, _,
		_, _, A, A, A, D, E, A, A, A, _, _,
		_, _, _, _, F, G, H, I, _, _, _, _,
		_, _, _, _, _, F, I, _, _, _, _, _,
		_, _, _, _, _, _, _, _, _, _, _, _,

		_, _, _, _, _, _, _, _, _, _, _, _,
		_, _, _, _, _, _, _, _, _, _, _, _,
		_, _, _, _, _, _, _, _, _, _, _, _,
		_, _, _, _, _, _, _, _, _, _, _, _,
		_, _, _, _, _, _, _, _, _, _, _, _,
		_, _, _, _, _, _, _, _, _, _, _, _,
		_, _, _, _, _, _, _, _, _, _, _, _,

		_, _, _, _, _, _, _, _, _, _, _, _,
		_, _, _, _, _, _, _, _, _, _, _, _,
		_, _, _, _, B, A, A, C, _, _, _, _,
		_, _, _, A, A, D, E, A, A, _, _, _,
		_, _, _, _, F, G, H, I, _, _, _, _,
		_, _, _, _, _, F, I, _, _, _, _, _,
		_, _, _, _, _, _, _, _, _, _, _, _,

		_, _, _, _, _, _, _, _, _, _, _, _,
		_, _, _, _, _, _, _, _, _, _, _, _,
		_, _, _, _, _, _, _, _, _, _, _, _,
		_, _, _, _, _, _, _, _, _, _, _, _,
		_, _, _, _, _, _, _, _, _, _, _, _,
		_, _, _, _, _, _, _, _, _, _, _, _,
		_, _, _, _, _, _, _, _, _, _, _, _,

		_, _, _, _, _, _, _, _, _, _, _, _,
		_, _, _, _, _, A, A, _, _, _, _, _,
		_, _, A, A, _, L, L, _, A, A, _, _,
		_, _, _, L, _, _, _, _, L, _, _, _,
		_, _, _, _, _, _, _, _, _, _, _, _,
		_, _, _, _, _, _, _, _, _, _, _, _,
		_, _, _, _, _, _, _, _, _, _, _, _,

		_, _, _, A, A, A, A, A, A, _, _, _,
		_, _, A, A, _, A, A, _, A, A, _, _,
		_, _, _, A, B, A, A, C, A, _, _, _,
		_, _, _, A, A, D, E, A, A, _, _, _,
		_, _, _, _, F, G, H, I, _, _, _, _,
		_, _, _, _, _, F, I, _, _, _, _, _,
		_, _, _, _, _, _, _, _, _, _, _, _,

		_, _, _, _, _, _, _, _, _, _, _, _,
		_, _, _, _, _, A, A, _, _, _, _, _,
		_, _, _, _, _, A, A, _, _, _, _, _,
		_, _, _, _, A, _, _, A, _, _, _, _,
		_, _, _, _, _, _, _, _, _, _, _, _,
		_, _, _, _, _, _, _, _, _, _, _, _,
		_, _, _, _, _, _, _, _, _, _, _, _,

		_, _, _, _, _, _, _, _, _, _, _, _,
		_, _, _, _, _, _, _, _, _, _, _, _,
		_, _, _, _, _, _, _, _, _, _, _, _,
		_, _, _, _, _, _, _, _, _, _, _, _,
		_, _, _, _, _, _, _, _, _, _, _, _,
		_, _, _, _, _, _, _, _, _, _, _, _,
		_, _, _, _, _, _, _, _, _, _, _, _,

		_, _, _, _, _, _, _, _, _, _, _, _,
		_, _, _, _, _, _, _, _, _, _, _, _,
		_, _, _, _, _, H, M, _, _, _, _, _,
		_, _, _, _, N, O, P, Q, _, _, _, _,
		_, _, _, _, _, J, K, _, _, _, _, _,
		_, _, _, _, _, _, _, _, _, _, _, _,
		_, _, _, _, _, _, _, _, _, _, _, _,

		_, _, _, _, _, _, _, _, _, _, _, _,
		_, _, _, _, _, _, _, _, _, _, _, _,
		_, _, _, _, _, _, _, _, _, _, _, _,
		_, _, _, _, _, _, _, _, _, _, _, _,
		_, _, _, _, _, _, _, _, _, _, _, _,
		_, _, _, _, _, _, _, _, _, _, _, _,
		_, _, _, _, _, _, _, _, _, _, _, _,

		_, _, _, _, _, _, _, _, _, _, _, _,
		_, _, _, _, _, _, _, _, _, _, _, _,
		_, _, _, _, _, _, H, M, _, _, _, _,
		_, _, _, _, _, N, O, P, Q, _, _, _,
		_, _, _, _, _, _, J, K, _, _, _, _,
		_, _, _, _, _, _, _, _, _, _, _, _,
		_, _, _, _, _, _, _, _, _, _, _, _,
	},
	yslice_prob = {
		{ypos=0,prob=200},
		{ypos=1,prob=200},
		{ypos=2,prob=200},
	}
}
