local _ = {name = "air", prob = 0}
local A = {
	name = "moreblocks:slab_coral_skeleton",
	param2 = 1,
	prob = 255,
	force_place = true
}
local B = {
	name = "default:coral_skeleton",
	prob = 255,
	force_place = true
}
local C = {
	name = "moreblocks:slab_coral_skeleton",
	param2 = 20,
	prob = 255,
	force_place = true
}
local D = {
	name = "moreblocks:slab_coral_skeleton",
	param2 = 2,
	prob = 255,
	force_place = true
}
local E = {
	name = "moreblocks:stair_coral_skeleton",
	param2 = 3,
	prob = 255,
	force_place = true
}
local F = {
	name = "moreblocks:slab_coral_skeleton",
	param2 = 22,
	prob = 255,
	force_place = true
}
local G = {
	name = "moreblocks:slab_coral_skeleton",
	prob = 255,
	force_place = true
}
local H = {
	name = "moreblocks:slab_coral_skeleton",
	param2 = 21,
	prob = 255,
	force_place = true
}
local I = {
	name = "moreblocks:stair_coral_skeleton",
	param2 = 23,
	prob = 255,
	force_place = true
}
local J = {
	name = "moreblocks:stair_coral_skeleton",
	param2 = 1,
	prob = 255,
	force_place = true
}
local K = {
	name = "moreblocks:stair_coral_skeleton",
	param2 = 21,
	prob = 255,
	force_place = true
}
local L = {
	name = "moreblocks:slab_coral_skeleton",
	param2 = 23,
	prob = 255,
	force_place = true
}
local M = {
	name = "moreblocks:stair_coral_skeleton",
	param2 = 12,
	prob = 255,
	force_place = true
}
local N = {
	name = "moreblocks:stair_coral_skeleton",
	param2 = 14,
	prob = 255,
	force_place = true
}
local O = {
	name = "moreblocks:stair_coral_skeleton",
	param2 = 5,
	prob = 255,
	force_place = true
}
local P = {
	name = "moreblocks:stair_coral_skeleton",
	param2 = 9,
	prob = 255,
	force_place = true
}
local Q = {
	name = "moreblocks:stair_coral_skeleton",
	prob = 255,
	force_place = true
}
local R = {
	name = "moreblocks:stair_coral_skeleton",
	param2 = 2,
	prob = 255,
	force_place = true
}
local S = {
	name = "moreblocks:slab_coral_skeleton",
	param2 = 3,
	prob = 255,
	force_place = true
}
local T = {
	name = "moreblocks:stair_coral_skeleton",
	param2 = 20,
	prob = 255,
	force_place = true
}
local U = {
	name = "moreblocks:stair_coral_skeleton",
	param2 = 22,
	prob = 255,
	force_place = true
}
local V = {
	name = "moreblocks:slab_coral_skeleton",
	param2 = 5,
	prob = 255,
	force_place = true
}
local W = {
	name = "moreblocks:slab_coral_skeleton",
	param2 = 9,
	prob = 255,
	force_place = true
}
return {
	size = {x = 5, y = 10, z = 19},
	data = { -- note that data is upside down
		_, _, _, _, _,
		_, _, _, _, _,
		_, _, _, _, _,
		_, _, A, _, _,
		_, _, _, _, _,
		_, _, _, _, _,
		_, _, _, _, _,
		_, _, _, _, _,
		_, _, _, _, _,
		_, _, _, _, _,

		_, _, _, _, _,
		_, _, _, _, _,
		_, _, _, _, _,
		_, _, B, _, _,
		_, _, _, _, _,
		_, _, _, _, _,
		_, _, _, _, _,
		_, _, _, _, _,
		_, _, _, _, _,
		_, _, _, _, _,

		_, _, _, _, _,
		_, _, _, _, _,
		_, _, _, _, _,
		_, _, C, _, _,
		_, _, D, _, _,
		_, _, _, _, _,
		_, _, _, _, _,
		_, _, _, _, _,
		_, _, _, _, _,
		_, _, _, _, _,

		_, _, _, _, _,
		_, _, _, _, _,
		_, _, _, _, _,
		_, _, _, _, _,
		_, _, B, _, _,
		_, _, E, _, _,
		_, _, _, _, _,
		_, _, _, _, _,
		_, _, _, _, _,
		_, _, _, _, _,

		_, _, _, _, _,
		_, _, _, _, _,
		_, _, _, _, _,
		_, _, _, _, _,
		_, _, F, _, _,
		_, _, G, _, _,
		_, _, _, _, _,
		_, _, _, _, _,
		_, _, _, _, _,
		_, _, _, _, _,

		_, _, _, _, _,
		_, _, _, _, _,
		_, _, _, _, _,
		_, _, _, _, _,
		_, _, _, _, _,
		_, _, B, _, _,
		_, _, E, _, _,
		_, _, _, _, _,
		_, _, _, _, _,
		_, _, _, _, _,

		_, _, _, _, _,
		_, _, _, _, _,
		_, _, _, _, _,
		_, _, _, _, _,
		_, _, _, _, _,
		_, _, H, _, _,
		_, _, A, _, _,
		_, _, _, _, _,
		_, _, _, _, _,
		_, _, _, _, _,

		_, _, _, _, _,
		I, _, _, _, I,
		J, _, _, _, J,
		I, _, _, _, I,
		J, _, _, _, I,
		_, _, _, _, _,
		_, _, B, _, _,
		_, _, E, _, _,
		_, _, _, _, _,
		_, _, _, _, _,

		B, _, _, _, B,
		E, _, _, _, E,
		K, _, _, _, K,
		E, _, _, _, E,
		_, _, _, _, _,
		A, _, H, _, A,
		_, _, K, _, _,
		_, _, _, _, _,
		_, _, _, _, _,
		_, _, _, _, _,

		E, _, _, _, E,
		_, _, _, _, _,
		_, _, L, _, _,
		_, M, _, N, _,
		I, _, _, _, I,
		C, O, _, P, F,
		_, _, B, _, _,
		_, _, E, _, _,
		_, _, _, _, _,
		_, _, _, _, _,

		_, _, _, _, _,
		_, _, _, _, _,
		_, _, _, _, _,
		J, M, _, N, J,
		I, _, _, _, I,
		Q, O, H, P, R,
		_, _, K, _, _,
		_, _, _, _, _,
		_, _, _, _, _,
		_, _, _, _, _,

		_, _, _, _, _,
		_, _, _, _, _,
		_, _, L, _, _,
		J, M, _, N, J,
		I, _, _, _, I,
		C, O, _, P, F,
		_, _, B, _, _,
		_, _, E, _, _,
		_, _, _, _, _,
		_, _, _, _, _,

		_, _, _, _, _,
		_, _, _, _, _,
		_, _, _, _, _,
		_, M, _, N, _,
		I, _, _, _, I,
		Q, O, H, P, R,
		_, _, K, _, _,
		_, _, _, _, _,
		_, _, _, _, _,
		_, _, _, _, _,

		_, _, _, _, _,
		I, _, _, _, I,
		J, _, L, _, J,
		I, _, _, _, I,
		J, _, _, _, J,
		H, O, _, P, F,
		_, _, B, _, _,
		_, _, E, _, _,
		_, _, _, _, _,
		_, _, _, _, _,

		B, _, _, _, B,
		E, _, _, _, E,
		K, _, _, _, K,
		M, _, _, _, E,
		_, _, _, _, _,
		_, _, L, _, _,
		_, S, S, S, _,
		_, _, _, _, _,
		_, _, _, _, _,
		_, _, _, _, _,

		E, _, _, _, E,
		_, _, _, _, _,
		_, _, _, _, _,
		_, _, _, _, _,
		_, _, _, _, _,
		_, _, I, _, _,
		_, T, B, U, _,
		T, D, B, D, U,
		_, V, _, W, _,
		_, D, _, S, _,

		_, _, _, _, _,
		_, _, _, _, _,
		_, _, _, _, _,
		_, _, _, _, _,
		_, _, F, _, _,
		_, _, B, _, _,
		_, _, K, _, _,
		_, H, _, H, _,
		_, _, _, _, _,
		_, _, _, _, _,

		_, _, _, _, _,
		_, _, _, _, _,
		_, _, _, _, _,
		_, _, _, _, _,
		_, _, F, _, _,
		_, _, K, _, _,
		_, _, E, _, _,
		_, _, _, _, _,
		_, A, _, A, _,
		_, _, _, _, _,

		_, _, _, _, _,
		_, _, _, _, _,
		_, _, _, _, _,
		_, _, _, _, _,
		_, _, _, _, _,
		_, _, I, _, _,
		_, _, _, _, _,
		_, _, _, _, _,
		_, _, _, _, _,
		_, _, _, _, _,
	},
	yslice_prob = {
		{ypos=0,prob=200},
		{ypos=1,prob=200},
		{ypos=2,prob=200},
		{ypos=3,prob=200},
		{ypos=4,prob=200},
		{ypos=5,prob=200},
	}
}
