local _ = {name = "air", prob = 0}
local A = {
	name = "moreblocks:slope_coral_skeleton",
	param2 = 23,
	prob = 255,
	force_place = true
}
local B = {
	name = "default:coral_skeleton",
	param2 = 1,
	prob = 255,
	force_place = true
}
local C = {
	name = "moreblocks:slope_coral_skeleton",
	param2 = 21,
	prob = 255,
	force_place = true
}
local D = {
	name = "moreblocks:slope_coral_skeleton",
	param2 = 1,
	prob = 255,
	force_place = true
}
local E = {
	name = "moreblocks:slope_coral_skeleton",
	param2 = 3,
	prob = 255,
	force_place = true
}
return {
	size = {x = 7, y = 8, z = 11},
	data = { -- note that data is upside down
		A, B, B, _, B, B, C,
		B, _, _, _, _, _, B,
		B, _, _, _, _, _, B,
		B, _, _, _, _, _, B,
		D, B, _, _, _, B, E,
		_, _, B, _, B, _, _,
		_, _, _, B, _, _, _,
		_, _, _, B, _, _, _,

		_, _, _, _, _, _, _,
		_, _, _, _, _, _, _,
		_, _, _, _, _, _, _,
		_, _, _, _, _, _, _,
		_, _, _, _, _, _, _,
		_, _, _, B, _, _, _,
		_, _, _, _, _, _, _,
		_, _, _, _, _, _, _,

		A, B, B, _, B, B, C,
		B, _, _, _, _, _, B,
		B, _, _, _, _, _, B,
		B, _, _, _, _, _, B,
		D, B, B, _, _, B, E,
		_, _, B, B, B, _, _,
		_, _, _, B, _, _, _,
		_, _, _, _, _, _, _,

		_, _, _, _, _, _, _,
		_, _, _, _, _, _, _,
		_, _, _, _, _, _, _,
		_, _, _, _, _, _, _,
		_, _, _, _, _, _, _,
		_, _, _, B, _, _, _,
		_, _, _, _, _, _, _,
		_, _, _, _, _, _, _,

		A, B, B, _, B, B, C,
		B, _, _, _, _, _, B,
		B, _, _, _, _, _, B,
		B, _, _, _, _, _, B,
		D, B, _, _, _, B, E,
		_, _, B, B, B, _, _,
		_, _, _, B, _, _, _,
		_, _, _, _, _, _, _,

		_, _, _, _, _, _, _,
		_, _, _, _, _, _, _,
		_, _, _, _, _, _, _,
		_, _, _, _, _, _, _,
		_, _, _, _, _, _, _,
		_, _, _, B, _, _, _,
		_, _, _, _, _, _, _,
		_, _, _, _, _, _, _,

		_, A, B, _, B, C, _,
		_, B, _, _, _, B, _,
		_, B, _, _, _, B, _,
		_, B, _, _, _, B, _,
		_, D, B, _, B, E, _,
		_, _, _, B, _, _, _,
		_, _, _, B, _, _, _,
		_, _, _, _, _, _, _,

		_, _, _, _, _, _, _,
		_, _, _, _, _, _, _,
		_, _, _, _, _, _, _,
		_, _, _, _, _, _, _,
		_, _, _, B, _, _, _,
		_, _, _, _, _, _, _,
		_, _, _, _, _, _, _,
		_, _, _, _, _, _, _,

		_, _, _, _, _, _, _,
		_, _, B, _, B, _, _,
		_, _, B, _, B, _, _,
		_, _, D, B, E, _, _,
		_, _, _, B, _, _, _,
		_, _, _, B, _, _, _,
		_, _, _, _, _, _, _,
		_, _, _, _, _, _, _,

		_, _, _, _, _, _, _,
		_, _, _, _, _, _, _,
		_, _, _, _, _, _, _,
		_, _, _, B, _, _, _,
		_, _, _, B, _, _, _,
		_, _, _, _, _, _, _,
		_, _, _, _, _, _, _,
		_, _, _, _, _, _, _,

		_, _, _, _, _, _, _,
		_, _, _, _, _, _, _,
		_, _, _, _, _, _, _,
		_, _, B, B, B, _, _,
		_, _, _, B, _, _, _,
		_, _, _, B, _, _, _,
		_, _, _, _, _, _, _,
		_, _, _, _, _, _, _,
	},
	yslice_prob = {
		{ypos=0,prob=200},
		{ypos=1,prob=200},
		{ypos=2,prob=200},
		{ypos=3,prob=200},
		{ypos=4,prob=200},
	}
}
